<?xml version="1.0" ?>
<!-- =================================================================================== -->
<!-- |    This document was autogenerated by xacro from myrg2ur10.urdf.xacro           | -->
<!-- |    EDITING THIS FILE BY HAND IS NOT RECOMMENDED                                 | -->
<!-- =================================================================================== -->
<robot name="rg2myur10">
  <link name="world"/>
  <joint name="world_link" type="fixed">
    <parent link="world"/>
    <child link="table"/>
    <origin rpy="0.0 0.0 0.0" xyz="0.42 0.0 -0.39"/>
  </joint>
  <material name="grey">
    <color rgba="0.8 0.8 0.8 1"/>
  </material>
  <link name="table">
    <visual>
      <geometry>
        <mesh filename="package://myur10_description/meshes/table/visual/table.dae"/>
      </geometry>
      <material name="grey"/>
    </visual>
    <collision>
      <geometry>
        <mesh filename="package://myur10_description/meshes/table/collision/table.obj"/>
      </geometry>
    </collision>
  </link>
  <gazebo>
    <plugin filename="libgazebo_ros_control.so" name="ros_control">
      <!--robotNamespace>/</robotNamespace-->
      <!--robotSimType>gazebo_ros_control/DefaultRobotHWSim</robotSimType-->
    </plugin>
    <!--
    <plugin name="gazebo_ros_power_monitor_controller" filename="libgazebo_ros_power_monitor.so">
      <alwaysOn>true</alwaysOn>
      <updateRate>1.0</updateRate>
      <timeout>5</timeout>
      <powerStateTopic>power_state</powerStateTopic>
      <powerStateRate>10.0</powerStateRate>
      <fullChargeCapacity>87.78</fullChargeCapacity>     
      <dischargeRate>-474</dischargeRate>
      <chargeRate>525</chargeRate>
      <dischargeVoltage>15.52</dischargeVoltage>
      <chargeVoltage>16.41</chargeVoltage>
    </plugin>
-->
  </gazebo>
  <!--
  Author: Kelsey Hawkins
  Contributers: Jimmy Da Silva, Ajit Krisshna N L, Muhammad Asif Rana
-->
  <link name="rg2_base_link">
    </link>
  <joint name="base_fixed_joint" type="fixed">
    <parent link="rg2_base_link"/>
    <child link="hand_link"/>
    <origin rpy="0 0 0" xyz="0.000 0.000 0.000"/>
  </joint>
  <link name="hand_link">
    <collision>
      <origin rpy="0.00 0.00 0.00" xyz="0.00 0.00 0.00"/>
      <geometry>
        <mesh filename="package://rg2_description/meshes/collision/RG2_Hand_col.STL"/>
      </geometry>
    </collision>
    <visual>
      <origin rpy="0.00 0.00 0.00" xyz="0.00 0.00 0.00"/>
      <geometry>
        <mesh filename="package://rg2_description/meshes/visual/RG2_Hand_vis.STL"/>
      </geometry>
    </visual>
    <!-- <inertial>
            <origin xyz="0.058091 0.000192 -0.000016" rpy="0.00 0.00 0.00"/>
            <mass value="0.524520"/>
            <inertia ixx="0.000193" ixy="0.000000" ixz="0.000000"
                     iyy="0.000564" iyz="-0.000001"
                     izz="0.000636" />
        </inertial> -->
    <inertial>
      <origin rpy="0.00 0.00 0.00" xyz="0.061902 0.000129 -0.000005"/>
      <mass value="1.684558"/>
      <inertia ixx="0.000862" ixy="0.000000" ixz="0.000000" iyy="0.002401" iyz="-0.000001" izz="0.002620"/>
    </inertial>
  </link>
  <!-- Jari Kiri -->
  <joint name="gripper_joint" type="revolute">
    <parent link="hand_link"/>
    <child link="l_moment_arm_link"/>
    <origin rpy="0 0 0" xyz="0.105 0.017 0.010"/>
    <axis xyz="0 0 1"/>
    <limit effort="10.6" lower="-0.45" upper="1.570796327" velocity="3.14"/>
    <!-- <limit velocity="3.14" effort="100" lower="-3" upper="3" /> -->
    <dynamics damping="0.1" friction="0.0"/>
    <implicitSpringDamper>True</implicitSpringDamper>
  </joint>
  <transmission name="gripper_joint_tran">
    <type>transmission_interface/SimpleTransmission</type>
    <joint name="gripper_joint">
      <hardwareInterface>hardware_interface/EffortJointInterface</hardwareInterface>
    </joint>
    <actuator name="gripper_joint_motor">
      <hardwareInterface>hardware_interface/EffortJointInterface</hardwareInterface>
      <mechanicalReduction>1</mechanicalReduction>
    </actuator>
  </transmission>
  <link name="l_moment_arm_link">
    <collision>
      <origin rpy="0.00 0.00 0.00" xyz="0.00 0.00 0.00"/>
      <geometry>
        <mesh filename="package://rg2_description/meshes/collision/RG2_LeftMomentArm_col.STL"/>
      </geometry>
    </collision>
    <visual>
      <origin rpy="0.00 0.00 0.00" xyz="0.00 0.00 0.00"/>
      <geometry>
        <mesh filename="package://rg2_description/meshes/visual/RG2_LeftMomentArm_vis.STL"/>
      </geometry>
    </visual>
    <inertial>
      <origin rpy="0.00 0.00 0.00" xyz="0.017004 0.006397 -0.010300"/>
      <mass value="0.160209"/>
      <inertia ixx="0.000023" ixy="0.000019" ixz="0.000000" iyy="0.000072" iyz="0.000000" izz="0.000083"/>
    </inertial>
  </link>
  <joint name="l_finger_2_joint" type="revolute">
    <parent link="l_moment_arm_link"/>
    <child link="l_finger_link"/>
    <origin rpy="0 0 0" xyz="0.049 0.026 0.000"/>
    <axis xyz="0 0 1"/>
    <limit effort="10.6" lower="-1.570796327" upper="1.570796327" velocity="3.14"/>
    <!-- <limit velocity="3.14" effort="100" lower="-3" upper="3" /> -->
    <mimic joint="gripper_joint" multiplier="-1"/>
    <dynamics damping="0.1" friction="0.0"/>
    <implicitSpringDamper>True</implicitSpringDamper>
  </joint>
  <!-- <xacro:insert_transmission name="l_finger_2_joint" /> -->
  <link name="l_finger_link">
    <collision>
      <origin rpy="0.00 0.00 0.00" xyz="0.00 0.00 0.00"/>
      <geometry>
        <mesh filename="package://rg2_description/meshes/collision/RG2_LeftFinger_col.STL"/>
      </geometry>
    </collision>
    <visual>
      <origin rpy="0.00 0.00 0.00" xyz="0.00 0.00 0.00"/>
      <geometry>
        <mesh filename="package://rg2_description/meshes/visual/RG2_LeftFinger_vis.STL"/>
      </geometry>
    </visual>
    <inertial>
      <origin rpy="0.00 0.00 0.00" xyz="0.024695 -0.010178 -0.010001"/>
      <mass value="0.081638"/>
      <inertia ixx="0.000006" ixy="-0.000005" ixz="0.000000" iyy="0.000025" iyz="0.000000" izz="0.000026"/>
    </inertial>
  </link>
  <joint name="l_finger_passive_joint" type="revolute">
    <parent link="hand_link"/>
    <child link="l_truss_arm_link"/>
    <origin rpy="0 0 0" xyz="0.122 0.008 0.010"/>
    <axis xyz="0 0 1"/>
    <limit effort="10.6" lower="-1.570796327" upper="1.570796327" velocity="3.14"/>
    <!-- <limit velocity="3.14" effort="100" lower="-3" upper="3" /> -->
    <mimic joint="gripper_joint" multiplier="1"/>
    <dynamics damping="0.1" friction="0.0"/>
    <implicitSpringDamper>True</implicitSpringDamper>
  </joint>
  <!-- <xacro:insert_transmission name="l_finger_passive_joint" /> -->
  <link name="l_truss_arm_link">
    <collision>
      <origin rpy="0.00 0.00 0.00" xyz="0.00 0.00 0.00"/>
      <geometry>
        <mesh filename="package://rg2_description/meshes/collision/RG2_LeftTrussArm_col.STL"/>
      </geometry>
    </collision>
    <visual>
      <origin rpy="0.00 0.00 0.00" xyz="0.00 0.00 0.00"/>
      <geometry>
        <mesh filename="package://rg2_description/meshes/visual/RG2_LeftTrussArm_vis.STL"/>
      </geometry>
    </visual>
    <inertial>
      <origin rpy="0.00 0.00 0.00" xyz="0.023075 0.012136 -0.010000"/>
      <mass value="0.065927"/>
      <inertia ixx="0.000010" ixy="0.000010" ixz="0.000000" iyy="0.000024" iyz="0.000000" izz="0.000025"/>
    </inertial>
  </link>
  <!-- Jari Kanan -->
  <joint name="r_finger_1_joint" type="revolute">
    <parent link="hand_link"/>
    <child link="r_moment_arm_link"/>
    <origin rpy="0 0 0" xyz="0.105 -0.017 0.010"/>
    <axis xyz="0 0 1"/>
    <limit effort="10.6" lower="-1.570796327" upper="1.570796327" velocity="3.14"/>
    <!-- <limit velocity="3.14" effort="100" lower="-3" upper="3" /> -->
    <mimic joint="gripper_joint" multiplier="-1"/>
    <dynamics damping="0.1" friction="0.0"/>
    <implicitSpringDamper>True</implicitSpringDamper>
  </joint>
  <!-- <xacro:insert_transmission name="r_finger_1_joint" /> -->
  <link name="r_moment_arm_link">
    <collision>
      <origin rpy="0.00 0.00 0.00" xyz="0.00 0.00 0.00"/>
      <geometry>
        <mesh filename="package://rg2_description/meshes/collision/RG2_RightMomentArm_col.STL"/>
      </geometry>
    </collision>
    <visual>
      <origin rpy="0.00 0.00 0.00" xyz="0.00 0.00 0.00"/>
      <geometry>
        <mesh filename="package://rg2_description/meshes/visual/RG2_RightMomentArm_vis.STL"/>
      </geometry>
    </visual>
    <inertial>
      <origin rpy="0.00 0.00 0.00" xyz="0.017004 -0.006397 -0.010300"/>
      <mass value="0.160209"/>
      <inertia ixx="0.000023" ixy="-0.000019" ixz="0.000000" iyy="0.000072" iyz="0.000000" izz="0.000083"/>
    </inertial>
  </link>
  <joint name="r_finger_2_joint" type="revolute">
    <parent link="r_moment_arm_link"/>
    <child link="r_finger_link"/>
    <origin rpy="0 0 0" xyz="0.049 -0.026 0.000"/>
    <axis xyz="0 0 1"/>
    <limit effort="10.6" lower="-1.570796327" upper="1.570796327" velocity="3.14"/>
    <!-- <limit velocity="3.14" effort="100" lower="-3" upper="3" /> -->
    <mimic joint="gripper_joint" multiplier="1"/>
    <dynamics damping="0.1" friction="0.0"/>
    <implicitSpringDamper>True</implicitSpringDamper>
  </joint>
  <!-- <xacro:insert_transmission name="r_finger_2_joint" /> -->
  <link name="r_finger_link">
    <collision>
      <origin rpy="0.00 0.00 0.00" xyz="0.00 0.00 0.00"/>
      <geometry>
        <mesh filename="package://rg2_description/meshes/collision/RG2_RightFinger_col.STL"/>
      </geometry>
    </collision>
    <visual>
      <origin rpy="0.00 0.00 0.00" xyz="0.00 0.00 0.00"/>
      <geometry>
        <mesh filename="package://rg2_description/meshes/visual/RG2_RightFinger_vis.STL"/>
      </geometry>
    </visual>
    <inertial>
      <origin rpy="0.00 0.00 0.00" xyz="0.024695 0.010178 -0.010000"/>
      <mass value="0.081637"/>
      <inertia ixx="0.000006" ixy="0.000005" ixz="0.000000" iyy="0.000025" iyz="0.000000" izz="0.000026"/>
    </inertial>
  </link>
  <joint name="r_finger_passive_joint" type="revolute">
    <parent link="hand_link"/>
    <child link="r_truss_arm_link"/>
    <origin rpy="0 0 0" xyz="0.122 -0.008 0.010"/>
    <axis xyz="0 0 1"/>
    <limit effort="10.6" lower="-1.570796327" upper="1.570796327" velocity="3.14"/>
    <!-- <limit velocity="3.14" effort="100" lower="-3" upper="3" /> -->
    <mimic joint="gripper_joint" multiplier="-1"/>
    <dynamics damping="0.1" friction="0.0"/>
    <implicitSpringDamper>True</implicitSpringDamper>
  </joint>
  <link name="r_truss_arm_link">
    <collision>
      <origin rpy="0.00 0.00 0.00" xyz="0.00 0.00 0.00"/>
      <geometry>
        <mesh filename="package://rg2_description/meshes/collision/RG2_RightTrussArm_col.STL"/>
      </geometry>
    </collision>
    <visual>
      <origin rpy="0.00 0.00 0.00" xyz="0.00 0.00 0.00"/>
      <geometry>
        <mesh filename="package://rg2_description/meshes/visual/RG2_RightTrussArm_vis.STL"/>
      </geometry>
    </visual>
    <inertial>
      <origin rpy="0.00 0.00 0.00" xyz="0.023075 -0.012136 -0.010000"/>
      <mass value="0.065927"/>
      <inertia ixx="0.000010" ixy="-0.000010" ixz="0.000000" iyy="0.000024" iyz="0.000000" izz="0.000025"/>
    </inertial>
  </link>
  <!-- measured from model -->
  <link name="base_link">
    <visual>
      <geometry>
        <mesh filename="package://ur_description/meshes/ur10/visual/base.dae"/>
      </geometry>
      <material name="LightGrey">
        <color rgba="0.7 0.7 0.7 1.0"/>
      </material>
    </visual>
    <collision>
      <geometry>
        <mesh filename="package://ur_description/meshes/ur10/collision/base.stl"/>
      </geometry>
    </collision>
    <inertial>
      <mass value="4.0"/>
      <origin rpy="0 0 0" xyz="0.0 0.0 0.0"/>
      <inertia ixx="0.0061063308908" ixy="0.0" ixz="0.0" iyy="0.0061063308908" iyz="0.0" izz="0.01125"/>
    </inertial>
  </link>
  <joint name="shoulder_pan_joint" type="revolute">
    <parent link="base_link"/>
    <child link="shoulder_link"/>
    <origin rpy="0.0 0.0 0.0" xyz="0.0 0.0 0.1273"/>
    <axis xyz="0 0 1"/>
    <limit effort="330.0" lower="-3.141592654" upper="3.141592654" velocity="2.16"/>
    <dynamics damping="0.0" friction="0.0"/>
  </joint>
  <link name="shoulder_link">
    <visual>
      <geometry>
        <mesh filename="package://ur_description/meshes/ur10/visual/shoulder.dae"/>
      </geometry>
      <material name="LightGrey">
        <color rgba="0.7 0.7 0.7 1.0"/>
      </material>
    </visual>
    <collision>
      <geometry>
        <mesh filename="package://ur_description/meshes/ur10/collision/shoulder.stl"/>
      </geometry>
    </collision>
    <inertial>
      <mass value="7.778"/>
      <origin rpy="0 0 0" xyz="0.0 0.0 0.0"/>
      <inertia ixx="0.03147431257693659" ixy="0.0" ixz="0.0" iyy="0.03147431257693659" iyz="0.0" izz="0.021875624999999996"/>
    </inertial>
  </link>
  <joint name="shoulder_lift_joint" type="revolute">
    <parent link="shoulder_link"/>
    <child link="upper_arm_link"/>
    <origin rpy="0.0 1.570796327 0.0" xyz="0.0 0.220941 0.0"/>
    <axis xyz="0 1 0"/>
    <limit effort="330.0" lower="-3.141592654" upper="3.141592654" velocity="2.16"/>
    <dynamics damping="0.0" friction="0.0"/>
  </joint>
  <link name="upper_arm_link">
    <visual>
      <geometry>
        <mesh filename="package://ur_description/meshes/ur10/visual/upperarm.dae"/>
      </geometry>
      <material name="LightGrey">
        <color rgba="0.7 0.7 0.7 1.0"/>
      </material>
    </visual>
    <collision>
      <geometry>
        <mesh filename="package://ur_description/meshes/ur10/collision/upperarm.stl"/>
      </geometry>
    </collision>
    <inertial>
      <mass value="12.93"/>
      <origin rpy="0 0 0" xyz="0.0 -0.045 0.306"/>
      <inertia ixx="0.42175380379841093" ixy="0.0" ixz="0.0" iyy="0.42175380379841093" iyz="0.0" izz="0.03636562499999999"/>
    </inertial>
  </link>
  <joint name="elbow_joint" type="revolute">
    <parent link="upper_arm_link"/>
    <child link="forearm_link"/>
    <origin rpy="0.0 0.0 0.0" xyz="0.0 -0.1719 0.612"/>
    <axis xyz="0 1 0"/>
    <limit effort="150.0" lower="-3.141592654" upper="3.141592654" velocity="3.15"/>
    <dynamics damping="0.0" friction="0.0"/>
  </joint>
  <link name="forearm_link">
    <visual>
      <geometry>
        <mesh filename="package://ur_description/meshes/ur10/visual/forearm.dae"/>
      </geometry>
      <material name="LightGrey">
        <color rgba="0.7 0.7 0.7 1.0"/>
      </material>
    </visual>
    <collision>
      <geometry>
        <mesh filename="package://ur_description/meshes/ur10/collision/forearm.stl"/>
      </geometry>
    </collision>
    <inertial>
      <mass value="3.87"/>
      <origin rpy="0 0 0" xyz="0.0 0.0 0.28615"/>
      <inertia ixx="0.11106969409710458" ixy="0.0" ixz="0.0" iyy="0.11106969409710458" iyz="0.0" izz="0.010884375"/>
    </inertial>
  </link>
  <joint name="wrist_1_joint" type="revolute">
    <parent link="forearm_link"/>
    <child link="wrist_1_link"/>
    <origin rpy="0.0 1.570796327 0.0" xyz="0.0 0.0 0.5723"/>
    <axis xyz="0 1 0"/>
    <limit effort="54.0" lower="-3.141592654" upper="3.141592654" velocity="3.2"/>
    <dynamics damping="0.0" friction="0.0"/>
  </joint>
  <link name="wrist_1_link">
    <visual>
      <geometry>
        <mesh filename="package://ur_description/meshes/ur10/visual/wrist1.dae"/>
      </geometry>
      <material name="LightGrey">
        <color rgba="0.7 0.7 0.7 1.0"/>
      </material>
    </visual>
    <collision>
      <geometry>
        <mesh filename="package://ur_description/meshes/ur10/collision/wrist1.stl"/>
      </geometry>
    </collision>
    <inertial>
      <mass value="1.96"/>
      <origin rpy="0 0 0" xyz="0.0 0.1149 0.0"/>
      <inertia ixx="0.005108247956699999" ixy="0.0" ixz="0.0" iyy="0.005108247956699999" iyz="0.0" izz="0.005512499999999999"/>
    </inertial>
  </link>
  <joint name="wrist_2_joint" type="revolute">
    <parent link="wrist_1_link"/>
    <child link="wrist_2_link"/>
    <origin rpy="0.0 0.0 0.0" xyz="0.0 0.1149 0.0"/>
    <axis xyz="0 0 1"/>
    <limit effort="54.0" lower="-3.141592654" upper="3.141592654" velocity="3.2"/>
    <dynamics damping="0.0" friction="0.0"/>
  </joint>
  <link name="wrist_2_link">
    <visual>
      <geometry>
        <mesh filename="package://ur_description/meshes/ur10/visual/wrist2.dae"/>
      </geometry>
      <material name="LightGrey">
        <color rgba="0.7 0.7 0.7 1.0"/>
      </material>
    </visual>
    <collision>
      <geometry>
        <mesh filename="package://ur_description/meshes/ur10/collision/wrist2.stl"/>
      </geometry>
    </collision>
    <inertial>
      <mass value="1.96"/>
      <origin rpy="0 0 0" xyz="0.0 0.0 0.1157"/>
      <inertia ixx="0.005108247956699999" ixy="0.0" ixz="0.0" iyy="0.005108247956699999" iyz="0.0" izz="0.005512499999999999"/>
    </inertial>
  </link>
  <joint name="wrist_3_joint" type="revolute">
    <parent link="wrist_2_link"/>
    <child link="wrist_3_link"/>
    <origin rpy="0.0 0.0 0.0" xyz="0.0 0.0 0.1157"/>
    <axis xyz="0 1 0"/>
    <limit effort="54.0" lower="-3.141592654" upper="3.141592654" velocity="3.2"/>
    <dynamics damping="0.0" friction="0.0"/>
  </joint>
  <link name="wrist_3_link">
    <visual>
      <geometry>
        <mesh filename="package://ur_description/meshes/ur10/visual/wrist3.dae"/>
      </geometry>
      <material name="LightGrey">
        <color rgba="0.7 0.7 0.7 1.0"/>
      </material>
    </visual>
    <collision>
      <geometry>
        <mesh filename="package://ur_description/meshes/ur10/collision/wrist3.stl"/>
      </geometry>
    </collision>
    <inertial>
      <mass value="0.202"/>
      <origin rpy="1.570796327 0 0" xyz="0.0 0.07695 0.0"/>
      <inertia ixx="0.00011792166116465" ixy="0.0" ixz="0.0" iyy="0.00011792166116465" iyz="0.0" izz="0.00020452500000000002"/>
    </inertial>
  </link>
  <joint name="ee_fixed_joint" type="fixed">
    <parent link="wrist_3_link"/>
    <child link="ee_link"/>
    <origin rpy="0.0 0.0 1.570796327" xyz="0.0 0.0922 0.0"/>
  </joint>
  <link name="ee_link">
    <collision>
      <geometry>
        <box size="0.01 0.01 0.01"/>
      </geometry>
      <origin rpy="0 0 0" xyz="-0.01 0 0"/>
    </collision>
  </link>
  <transmission name="shoulder_pan_trans">
    <type>transmission_interface/SimpleTransmission</type>
    <joint name="shoulder_pan_joint">
      <hardwareInterface>hardware_interface/PositionJointInterface</hardwareInterface>
    </joint>
    <actuator name="shoulder_pan_motor">
      <mechanicalReduction>1</mechanicalReduction>
    </actuator>
  </transmission>
  <transmission name="shoulder_lift_trans">
    <type>transmission_interface/SimpleTransmission</type>
    <joint name="shoulder_lift_joint">
      <hardwareInterface>hardware_interface/PositionJointInterface</hardwareInterface>
    </joint>
    <actuator name="shoulder_lift_motor">
      <mechanicalReduction>1</mechanicalReduction>
    </actuator>
  </transmission>
  <transmission name="elbow_trans">
    <type>transmission_interface/SimpleTransmission</type>
    <joint name="elbow_joint">
      <hardwareInterface>hardware_interface/PositionJointInterface</hardwareInterface>
    </joint>
    <actuator name="elbow_motor">
      <mechanicalReduction>1</mechanicalReduction>
    </actuator>
  </transmission>
  <transmission name="wrist_1_trans">
    <type>transmission_interface/SimpleTransmission</type>
    <joint name="wrist_1_joint">
      <hardwareInterface>hardware_interface/PositionJointInterface</hardwareInterface>
    </joint>
    <actuator name="wrist_1_motor">
      <mechanicalReduction>1</mechanicalReduction>
    </actuator>
  </transmission>
  <transmission name="wrist_2_trans">
    <type>transmission_interface/SimpleTransmission</type>
    <joint name="wrist_2_joint">
      <hardwareInterface>hardware_interface/PositionJointInterface</hardwareInterface>
    </joint>
    <actuator name="wrist_2_motor">
      <mechanicalReduction>1</mechanicalReduction>
    </actuator>
  </transmission>
  <transmission name="wrist_3_trans">
    <type>transmission_interface/SimpleTransmission</type>
    <joint name="wrist_3_joint">
      <hardwareInterface>hardware_interface/PositionJointInterface</hardwareInterface>
    </joint>
    <actuator name="wrist_3_motor">
      <mechanicalReduction>1</mechanicalReduction>
    </actuator>
  </transmission>
  <gazebo reference="shoulder_link">
    <selfCollide>true</selfCollide>
  </gazebo>
  <gazebo reference="upper_arm_link">
    <selfCollide>true</selfCollide>
  </gazebo>
  <gazebo reference="forearm_link">
    <selfCollide>true</selfCollide>
  </gazebo>
  <gazebo reference="wrist_1_link">
    <selfCollide>true</selfCollide>
  </gazebo>
  <gazebo reference="wrist_3_link">
    <selfCollide>true</selfCollide>
  </gazebo>
  <gazebo reference="wrist_2_link">
    <selfCollide>true</selfCollide>
  </gazebo>
  <gazebo reference="ee_link">
    <selfCollide>true</selfCollide>
  </gazebo>
  <!-- ROS base_link to UR 'Base' Coordinates transform -->
  <link name="base"/>
  <joint name="base_link-base_fixed_joint" type="fixed">
    <!-- NOTE: this rotation is only needed as long as base_link itself is
                 not corrected wrt the real robot (ie: rotated over 180
                 degrees)
      -->
    <origin rpy="0 0 -3.141592654" xyz="0 0 0"/>
    <parent link="base_link"/>
    <child link="base"/>
  </joint>
  <!-- Frame coincident with all-zeros TCP on UR controller -->
  <link name="tool0"/>
  <joint name="wrist_3_link-tool0_fixed_joint" type="fixed">
    <origin rpy="-1.570796327 0 0" xyz="0 0.0922 0"/>
    <parent link="wrist_3_link"/>
    <child link="tool0"/>
  </joint>
  <joint name="realsense_camera_joint" type="fixed">
    <origin rpy="0 0 0" xyz="0.1 0 0.038"/>
    <parent link="hand_link"/>
    <child link="realsense_link"/>
  </joint>

  <link name="realsense_link">
    <visual>
      <!-- the mesh origin is at front plate in between the two infrared camera axes -->
      <origin rpy="1.57079632679 0 1.57079632679" xyz="0.0 -0.0 0"/>
      <geometry>
        <!-- <box size="${d435_cam_width} ${d435_cam_height} ${d435_cam_depth}"/> -->
        <mesh filename="package://realsense2_description/meshes/d435.dae" />
      </geometry>
      <material name="DarkGrey">
        <color rgba="0.3 0.3 0.3 1.0"/>
      </material>
    </visual>
    <collision>
      <origin rpy="0 0 0" xyz="0 -0.0175 0"/>
      <geometry>
        <box size="0.02505 0.09 0.025"/>
      </geometry>
    </collision>
    <inertial>
      <!-- The following are not reliable values, and should not be used for modeling -->
      <mass value="0.072"/>
      <origin xyz="0 0 0"/>
      <inertia ixx="0.003881243" ixy="0.0" ixz="0.0" iyy="0.000498940" iyz="0.0" izz="0.003879257"/>
    </inertial>
  </link>

  <joint name="realsense_optical_joint" type="fixed">
    <origin rpy="-1.571 0 -1.571" xyz="0.0 0.015 0.0"/>
    <parent link="realsense_link"/>
    <child link="realsense_color_optical_frame"/>
  </joint>

  <joint name="realsense_fake_joint" type="fixed">
    <origin rpy="0.0 0.0 0.0" xyz="0.0 0.015 0.0"/>
    <parent link="realsense_link"/>
    <child link="realsense_camera_frame"/>
  </joint>

  <link name="realsense_camera_frame">
    <inertial>
      <mass value="1e-6"/>
      <origin rpy="0 0 0" xyz="0.0 0.0 0.0"/>
      <inertia ixx="1e-6" ixy="0.0" ixz="0.0" iyy="1e-6" iyz="0.0" izz="1e-6"/>
    </inertial>
  </link>

  <link name="realsense_color_optical_frame">
    <inertial>
      <mass value="1e-6"/>
      <origin rpy="0 0 0" xyz="0.0 0.0 0.0"/>
      <inertia ixx="1e-6" ixy="0.0" ixz="0.0" iyy="1e-6" iyz="0.0" izz="1e-6"/>
    </inertial>
  </link>

  <joint name="realsense_rgb2depth_virtual_joint" type="fixed">
    <origin rpy="0.0 0.0 0.0" xyz="0.0 0.0 0.0"/>
    <parent link="realsense_color_optical_frame"/>
    <child link="realsense_depth_optical_frame"/>
  </joint>

  <link name="realsense_depth_optical_frame"></link>
  <joint name="ee_rg2_fixed_joint" type="fixed">
    <parent link="tool0"/>
    <child link="rg2_base_link"/>
    <origin rpy="0 -1.570796327 0" xyz="0 0 0.004"/>
  </joint>
  <joint name="base_joint" type="fixed">
    <parent link="world"/>
    <child link="base_link"/>
    <origin rpy="0.0 0.0 0.0" xyz="0 0 0"/>
  </joint>
</robot>
